2023-03-14 21:13:01,364 INFO    Thread-8  :22642 [wandb_setup.py:_flush():68] Configure stats pid to 22642
2023-03-14 21:13:01,365 INFO    Thread-8  :22642 [wandb_setup.py:_flush():68] Loading settings from /home/vikram/.config/wandb/settings
2023-03-14 21:13:01,365 INFO    Thread-8  :22642 [wandb_setup.py:_flush():68] Loading settings from /home/vikram/Desktop/Deep Learning/cs6910_assignment1/wandb/settings
2023-03-14 21:13:01,365 INFO    Thread-8  :22642 [wandb_setup.py:_flush():68] Loading settings from environment variables: {'_require_service': 'True', 'root_dir': '/home/vikram/Desktop/Deep Learning/cs6910_assignment1', 'entity': 'cs19b021', 'project': 'cs6910-assignment1', 'run_id': 'v8d4tsr5', 'sweep_param_path': '/home/vikram/Desktop/Deep Learning/cs6910_assignment1/wandb/sweep-g8kfz9im/config-v8d4tsr5.yaml', 'sweep_id': 'g8kfz9im'}
2023-03-14 21:13:01,365 INFO    Thread-8  :22642 [wandb_setup.py:_flush():68] Inferring run settings from compute environment: {'program_relpath': 'sweep_code.py', 'program': '/home/vikram/Desktop/Deep Learning/cs6910_assignment1/sweep_code.py'}
2023-03-14 21:13:01,365 INFO    Thread-8  :22642 [wandb_init.py:_log_setup():492] Logging user logs to /home/vikram/Desktop/Deep Learning/cs6910_assignment1/wandb/run-20230314_211301-v8d4tsr5/logs/debug.log
2023-03-14 21:13:01,366 INFO    Thread-8  :22642 [wandb_init.py:_log_setup():493] Logging internal logs to /home/vikram/Desktop/Deep Learning/cs6910_assignment1/wandb/run-20230314_211301-v8d4tsr5/logs/debug-internal.log
2023-03-14 21:13:01,366 INFO    Thread-8  :22642 [wandb_init.py:init():532] calling init triggers
2023-03-14 21:13:01,366 INFO    Thread-8  :22642 [wandb_init.py:init():538] wandb.init called with sweep_config: {'activation_function': 'sigmoid', 'batch_size': 16, 'beta': 0.95, 'beta1': 0.9, 'beta2': 0.999, 'dataset': 'fashion_mnist', 'epochs': 15, 'epsilon': 1e-08, 'hidden_size': 128, 'learning_rate': 0.0008, 'loss': 'cross_entropy', 'momentum': 0.9, 'num_hlayers': 4, 'optimizer': 'nadam', 'weight_decay': 0, 'weight_init': 'random'}
config: {}
2023-03-14 21:13:01,366 INFO    Thread-8  :22642 [wandb_init.py:init():588] starting backend
2023-03-14 21:13:01,366 INFO    Thread-8  :22642 [wandb_init.py:init():592] setting up manager
2023-03-14 21:13:01,393 INFO    Thread-8  :22642 [backend.py:_multiprocessing_setup():106] multiprocessing start_methods=fork,spawn,forkserver, using: spawn
2023-03-14 21:13:01,404 INFO    Thread-8  :22642 [wandb_init.py:init():599] backend started and connected
2023-03-14 21:13:01,411 INFO    Thread-8  :22642 [wandb_run.py:_config_callback():1250] config_cb None None {'activation_function': 'sigmoid', 'batch_size': 16, 'beta': 0.95, 'beta1': 0.9, 'beta2': 0.999, 'dataset': 'fashion_mnist', 'epochs': 15, 'epsilon': 1e-08, 'hidden_size': 128, 'learning_rate': 0.0008, 'loss': 'cross_entropy', 'momentum': 0.9, 'num_hlayers': 4, 'optimizer': 'nadam', 'weight_decay': 0, 'weight_init': 'random'}
2023-03-14 21:13:01,416 INFO    Thread-8  :22642 [wandb_init.py:init():687] updated telemetry
2023-03-14 21:13:01,440 INFO    Thread-8  :22642 [wandb_init.py:init():727] communicating run to backend with 60.0 second timeout
2023-03-14 21:13:02,591 INFO    Thread-8  :22642 [wandb_run.py:_on_init():2134] communicating current version
2023-03-14 21:13:02,798 INFO    Thread-8  :22642 [wandb_run.py:_on_init():2143] got version response upgrade_message: "wandb version 0.13.11 is available!  To upgrade, please run:\n $ pip install wandb --upgrade"

2023-03-14 21:13:02,798 INFO    Thread-8  :22642 [wandb_init.py:init():775] starting run threads in backend
2023-03-14 21:13:16,621 INFO    Thread-8  :22642 [wandb_run.py:_console_start():2114] atexit reg
2023-03-14 21:13:16,622 INFO    Thread-8  :22642 [wandb_run.py:_redirect():1969] redirect: SettingsConsole.WRAP_RAW
2023-03-14 21:13:16,622 INFO    Thread-8  :22642 [wandb_run.py:_redirect():2034] Wrapping output streams.
2023-03-14 21:13:16,622 INFO    Thread-8  :22642 [wandb_run.py:_redirect():2059] Redirects installed.
2023-03-14 21:13:16,622 INFO    Thread-8  :22642 [wandb_init.py:init():817] run started, returning control to user process
2023-03-14 21:23:26,814 INFO    Thread-2  :22642 [retry.py:__call__():172] Retry attempt failed:
Traceback (most recent call last):
  File "/home/vikram/miniconda3/envs/dlenv/lib/python3.9/site-packages/urllib3/connection.py", line 174, in _new_conn
    conn = connection.create_connection(
  File "/home/vikram/miniconda3/envs/dlenv/lib/python3.9/site-packages/urllib3/util/connection.py", line 72, in create_connection
    for res in socket.getaddrinfo(host, port, family, socket.SOCK_STREAM):
  File "/home/vikram/miniconda3/envs/dlenv/lib/python3.9/socket.py", line 954, in getaddrinfo
    for res in _socket.getaddrinfo(host, port, family, type, proto, flags):
socket.gaierror: [Errno -3] Temporary failure in name resolution

During handling of the above exception, another exception occurred:

Traceback (most recent call last):
  File "/home/vikram/miniconda3/envs/dlenv/lib/python3.9/site-packages/urllib3/connectionpool.py", line 703, in urlopen
    httplib_response = self._make_request(
  File "/home/vikram/miniconda3/envs/dlenv/lib/python3.9/site-packages/urllib3/connectionpool.py", line 386, in _make_request
    self._validate_conn(conn)
  File "/home/vikram/miniconda3/envs/dlenv/lib/python3.9/site-packages/urllib3/connectionpool.py", line 1042, in _validate_conn
    conn.connect()
  File "/home/vikram/miniconda3/envs/dlenv/lib/python3.9/site-packages/urllib3/connection.py", line 358, in connect
    self.sock = conn = self._new_conn()
  File "/home/vikram/miniconda3/envs/dlenv/lib/python3.9/site-packages/urllib3/connection.py", line 186, in _new_conn
    raise NewConnectionError(
urllib3.exceptions.NewConnectionError: <urllib3.connection.HTTPSConnection object at 0x7f22cad9daf0>: Failed to establish a new connection: [Errno -3] Temporary failure in name resolution

During handling of the above exception, another exception occurred:

Traceback (most recent call last):
  File "/home/vikram/miniconda3/envs/dlenv/lib/python3.9/site-packages/requests/adapters.py", line 489, in send
    resp = conn.urlopen(
  File "/home/vikram/miniconda3/envs/dlenv/lib/python3.9/site-packages/urllib3/connectionpool.py", line 787, in urlopen
    retries = retries.increment(
  File "/home/vikram/miniconda3/envs/dlenv/lib/python3.9/site-packages/urllib3/util/retry.py", line 592, in increment
    raise MaxRetryError(_pool, url, error or ResponseError(cause))
urllib3.exceptions.MaxRetryError: HTTPSConnectionPool(host='api.wandb.ai', port=443): Max retries exceeded with url: /graphql (Caused by NewConnectionError('<urllib3.connection.HTTPSConnection object at 0x7f22cad9daf0>: Failed to establish a new connection: [Errno -3] Temporary failure in name resolution'))

During handling of the above exception, another exception occurred:

Traceback (most recent call last):
  File "/home/vikram/miniconda3/envs/dlenv/lib/python3.9/site-packages/wandb/sdk/lib/retry.py", line 131, in __call__
    result = self._call_fn(*args, **kwargs)
  File "/home/vikram/miniconda3/envs/dlenv/lib/python3.9/site-packages/wandb/sdk/internal/internal_api.py", line 242, in execute
    return self.client.execute(*args, **kwargs)  # type: ignore
  File "/home/vikram/miniconda3/envs/dlenv/lib/python3.9/site-packages/wandb/vendor/gql-0.2.0/wandb_gql/client.py", line 52, in execute
    result = self._get_result(document, *args, **kwargs)
  File "/home/vikram/miniconda3/envs/dlenv/lib/python3.9/site-packages/wandb/vendor/gql-0.2.0/wandb_gql/client.py", line 60, in _get_result
    return self.transport.execute(document, *args, **kwargs)
  File "/home/vikram/miniconda3/envs/dlenv/lib/python3.9/site-packages/wandb/vendor/gql-0.2.0/wandb_gql/transport/requests.py", line 38, in execute
    request = requests.post(self.url, **post_args)
  File "/home/vikram/miniconda3/envs/dlenv/lib/python3.9/site-packages/requests/api.py", line 115, in post
    return request("post", url, data=data, json=json, **kwargs)
  File "/home/vikram/miniconda3/envs/dlenv/lib/python3.9/site-packages/requests/api.py", line 59, in request
    return session.request(method=method, url=url, **kwargs)
  File "/home/vikram/miniconda3/envs/dlenv/lib/python3.9/site-packages/requests/sessions.py", line 587, in request
    resp = self.send(prep, **send_kwargs)
  File "/home/vikram/miniconda3/envs/dlenv/lib/python3.9/site-packages/requests/sessions.py", line 701, in send
    r = adapter.send(request, **kwargs)
  File "/home/vikram/miniconda3/envs/dlenv/lib/python3.9/site-packages/requests/adapters.py", line 565, in send
    raise ConnectionError(e, request=request)
requests.exceptions.ConnectionError: HTTPSConnectionPool(host='api.wandb.ai', port=443): Max retries exceeded with url: /graphql (Caused by NewConnectionError('<urllib3.connection.HTTPSConnection object at 0x7f22cad9daf0>: Failed to establish a new connection: [Errno -3] Temporary failure in name resolution'))
2023-03-14 21:25:44,218 WARNING MsgRouterThr:22642 [router.py:message_loop():77] message_loop has been closed
